Workbook
Name COI: 'Final Assessment'!$A$12:$A$13
Name Consultations: 'How to use the Tool'!$A$2:$A$4
Name Rating: 'How to use the Tool'!$A$1:$A$4
Name Safety: 'Final Assessment'!$A$1:$A$2
Name Setting: 'Final Assessment'!$A$5:$A$8
Name Type: 'Final Assessment'!$C$10:$C$14

Sheet How to use the Tool
A1: Rating
A2: Acceptable
A3: Concern
A4: Unacceptable
A9: Clinical Supervision Consultation Record Audit
A13: The Records Audit Tool has been designed to capture information from 10 up to 20 records routinely and is adapted from the NHSE tool for consultation audits for General Practitioners. Start using the Record Audit worksheet and enter your data here. Information including the scoring will be automatically transferred to the Record Report. The Record Report enables you to provide a narrative covering the background to the review, the methodology used and the conclusions you reach. Each consultation can be scored and commented on. There is a General Guidance section that explains some of the terminology and the rationale behind the audit tool The Criteria Guidance Tab gives specific guidance on some of the criteria used in the Audit Tool Use the Tabs on the worksheets to access the different pages The Expectation is that this is undertaken in line with the Clinical supervsion policy ONCE COMPLETE PLEASE UPLOAD TO CLARITY IN THE DIARY SECTION
A45: Developed by Dr Andrew Foulkes for NHS England 2015 andrew.foulkes1@nhs.net

Sheet Record Audit
A1: NHS England Record Review Template | B1: Date: | G1: Auditor:
A2: Unique Identifier or NHS number :
A3: Date of Consultation :
A4: Record number : | C4: 1 | D4: 2 | E4: 3 | F4: 4 | G4: 5 | H4: 6 | I4: 7 | J4: 8 | K4: 9 | L4: 10 | M4: 11 | N4: 12 | O4: 13 | P4: 14 | Q4: 15 | R4: 16 | S4: 17 | T4: 18 | U4: 19 | V4: 20 | W4: 21 | X4: 22 | Y4: 23 | Z4: 24 | AA4: 25 | AB4: 26 | AC4: 27 | AD4: 28 | AE4: 29 | AF4: 30 | AM4: Conditional ticks
A5: Prescriber Name: | AI5: Total | AJ5: Count | AM5: tick till | AN5: exclamation till | AP5: Entry list 1 | AQ5: Entry list 2 | AR5: Entry List 3
A6: Data entry and decision making
A7: Are the notes coherent and well-structured and include all contacts? | AI7: =SUM(C7:AF7) -> 0 | AJ7: =COUNT(C7:AF7) -> 0 | AK7: =AI7/AJ7 -> #DIV/0! | AM7: 0.8 | AN7: 0.6 | AO7: =IF(AH7=Pass,"N/A",AK7) -> #NAME? | AP7: 0 | AQ7: 0 | AR7: 0
A8: Problem appropriately summarised and Read coded | AI8: =SUM(C8:AF8) -> 0 | AJ8: =COUNT(C8:AF8) -> 0 | AK8: =AI8/AJ8 -> #DIV/0!
A9: Is there a record of the history of the presenting complaint with documentation of relevant positive features? | AI9: =SUM(C9:AF9) -> 0 | AJ9: =COUNT(C9:AF9) -> 0 | AK9: =AI9/AJ9 -> #DIV/0! | AM9: 0.8 | AN9: 0.6 | AO9: =IF(AH9=Pass,"N/A",AK9) -> #NAME? | AP9: 0.5 | AQ9: 1 | AR9: 0.5
A10: Is there a record of the history of the presenting complaint with documentation of relevant negative features? | AI10: =SUM(C10:AF10) -> 0 | AJ10: =COUNT(C10:AF10) -> 0 | AK10: =AI10/AJ10 -> #DIV/0! | AM10: 0.9 | AN10: 0.8 | AO10: =IF(AH10=Pass,"N/A",AK10) -> #NAME? | AP10: 1 | AQ10: N | AR10: 1
A11: Is there a record of any relevant clinical examination findings? | AI11: =SUM(C11:AF11) -> 0 | AJ11: =COUNT(C11:AF11) -> 0 | AK11: =AI11/AJ11 -> #DIV/0! | AP11: N | AR11: N
A12: Makes appropriate diagnostic decisions based on the information acquired, including referral, with a recording of the working diagnosis | AI12: =SUM(C12:AF12) -> 0 | AJ12: =COUNT(C12:AF12) -> 0 | AK12: =AI12/AJ12 -> #DIV/0!
A13: Prescribing | AM13: 0.5 | AN13: 0.3
A14: Is the prescribing for this consultation within current acceptable guidelines? | AI14: =SUM(C14:AF14) -> 0 | AJ14: =COUNT(C14:AF14) -> 0 | AK14: =AI14/AJ14 -> #DIV/0! | AM14: 0.7 | AN14: 0.4 | AO14: =IF(AH14=Pass,"N/A",AK14) -> #NAME?
A15: Appropriate advice given regarding common side effects/interactions? | AI15: =SUM(C15:AF15) -> 0 | AJ15: =COUNT(C15:AF15) -> 0 | AK15: =AI15/AJ15 -> #DIV/0! | AM15: 0.7 | AN15: 0.4 | AO15: =IF(AH15=Pass,"N/A",AK15) -> #NAME?
A16: Has there been an up to date medicines review? | AI16: =SUM(C16:AF16) -> 0 | AJ16: =COUNT(C16:AF16) -> 0 | AK16: =AI16/AJ16 -> #DIV/0! | AM16: 0.7 | AN16: 0.4 | AO16: =IF(AH16=Pass,"N/A",AK16) -> #NAME?
A17: Clinical Guidelines and Planning | AM17: 0.9 | AN17: 0.8 | AO17: =IF(AH17=Pass,"N/A",AK17) -> #NAME?
A18: Follows formally agreed clinical practice guidelines & procedures (national & local) including appropriate referrals made? | AI18: =SUM(C18:AF18) -> 0 | AJ18: =COUNT(C18:AF18) -> 0 | AK18: =AI18/AJ18 -> #DIV/0! | AM18: 0.8 | AN18: 0.6 | AO18: =IF(AH18=Pass,"N/A",AK18) -> #NAME?
A19: Is there a record in sufficient detail of the continuing care arrangements and / or safety net plan? | AI19: =SUM(C19:AF19) -> 0 | AJ19: =COUNT(C19:AF19) -> 0 | AK19: =AI19/AJ19 -> #DIV/0!
A20: Investigations
A21: Have all the radiology and pathology results been acted on appropriately? | AI21: =SUM(C21:AF21) -> 0 | AJ21: =COUNT(C21:AF21) -> 0 | AK21: =AI21/AJ21 -> #DIV/0!
A22: totals: | C22: =SUM(C7:C21) -> 0 | D22: =SUM(D7:D21) -> 0 | E22: =SUM(E7:E21) -> 0 | F22: =SUM(F7:F21) -> 0 | G22: =SUM(G7:G21) -> 0 | H22: =SUM(H7:H21) -> 0 | I22: =SUM(I7:I21) -> 0 | J22: =SUM(J7:J21) -> 0 | ... AI22: =SUM(AI7:AI21) -> 0 | AJ22: =COUNT(C22:AF22) -> 30
C23: =SUM(C7:C21) -> 0 | D23: =SUM(D7:D21) -> 0 | E23: =SUM(E7:E21) -> 0 | F23: =SUM(F7:F21) -> 0 | G23: =SUM(G7:G21) -> 0 | H23: =SUM(H7:H21) -> 0 | I23: =SUM(I7:I21) -> 0 | J23: =SUM(J7:J21) -> 0 | ... AF23: =SUM(AF7:AF21) -> 0
A24: Acceptable = 1 (fully compliant) | C24: =COUNTIF(C5:C21,"1") -> 0 | D24: =COUNTIF(D5:D21,"1") -> 0 | E24: =COUNTIF(E5:E21,"1") -> 0 | F24: =COUNTIF(F5:F21,"1") -> 0 | G24: =COUNTIF(G5:G21,"1") -> 0 | H24: =COUNTIF(H5:H21,"1") -> 0 | I24: =COUNTIF(I5:I21,"1") -> 0 | J24: =COUNTIF(J5:J21,"1") -> 0 | ... AH24: =COUNTIF(AH5:AH21,"1") -> 0 | AI24: =SUM(C24:AF24) -> 0
A25: Cause for Concern = 0.5 (partially compliant) | C25: =COUNTIF(C6:C21,"0.5") -> 0 | D25: =COUNTIF(D6:D21,"0.5") -> 0 | E25: =COUNTIF(E6:E21,"0.5") -> 0 | F25: =COUNTIF(F6:F21,"0.5") -> 0 | G25: =COUNTIF(G6:G21,"0.5") -> 0 | H25: =COUNTIF(H6:H21,"0.5") -> 0 | I25: =COUNTIF(I6:I21,"0.5") -> 0 | J25: =COUNTIF(J6:J21,"0.5") -> 0 | ... AH25: =COUNTIF(AH6:AH21,"0.5") -> 0 | AI25: =SUM(C25:AF25) -> 0
A26: Unacceptable = 0 (non-compliant) | C26: =COUNTIF(C7:C21,"0") -> 0 | D26: =COUNTIF(D7:D21,"0") -> 0 | E26: =COUNTIF(E7:E21,"0") -> 0 | F26: =COUNTIF(F7:F21,"0") -> 0 | G26: =COUNTIF(G7:G21,"0") -> 0 | H26: =COUNTIF(H7:H21,"0") -> 0 | I26: =COUNTIF(I7:I21,"0") -> 0 | J26: =COUNTIF(J7:J21,"0") -> 0 | ... AF26: =COUNTIF(AF7:AF21,"0") -> 0 | AI26: =SUM(C26:AF26) -> 0
A27: Not applicable = N | C27: =COUNTIF(C8:C22,"N") -> 0 | D27: =COUNTIF(D8:D22,"N") -> 0 | E27: =COUNTIF(E8:E22,"N") -> 0 | F27: =COUNTIF(F8:F22,"N") -> 0 | G27: =COUNTIF(G8:G22,"N") -> 0 | H27: =COUNTIF(H8:H22,"N") -> 0 | I27: =COUNTIF(I8:I22,"N") -> 0 | J27: =COUNTIF(J8:J22,"N") -> 0 | ... AF27: =COUNTIF(AF8:AF22,"N") -> 0 | AI27: =SUM(C27:AF27) -> 0
A29: Total number of criteria assessed | C29: =SUM(C24:AF24,C25:AF25,C26:AF26) -> 0 | D29: %
A30: Number of acceptable criteria | C30: =SUM(C24:AF24) -> 0 | D30: =C30/C29 -> #DIV/0!
A31: Number of cause for concerns | C31: =SUM(C25:AF25) -> 0 | D31: =(C31/C29) -> #DIV/0!
A32: Number of unacceptable | C32: =SUM(C26:AF26) -> 0 | D32: =(C32/C29) -> #DIV/0!

Sheet Record Report
B1: Record Report template
B3: Records Review of Consultations of: | C3: 10 | D3: ='Record Audit'!$AA$1 -> 0
B4: Auditor:
B5: Date of Review: | E5: Who has requested the review?
B6: Conflict of interest / bias checked? | E6: Is it a targeted review?
E7: Practice setting? | H7: Clinical Supervisor
B9: INTRODUCTION | I9: Guidance
B10: Routine record audit review. No concerns raised but routine review
B16: METHODOLOGY | I16: Guidance
B17: 10 sequential notes reviwed with a random choice of routine list
B25: THE CONSULTATIONS | C25: Surgery consultation (new)
B26: Please fill in table for each consultation | H26: complete field above
B27: 1
B28: Patient reference: | C28: ='Record Audit'!D2 -> 0 | G28: Date of consultation: | I28: ='Record Audit'!D3 -> 0
B30: Consultation Record (copy from clinical system if possible)
B34: Acceptable | C34: Click on the cell to the left and use the drop down list to select the overall rating of the consultation | E34: Comments / Actions required
C37: Scores for each criteria
B38: A | C38: ='Record Audit'!C24 -> 0
B39: C | C39: ='Record Audit'!C25 -> 0 | D39: Total
B40: U | C40: ='Record Audit'!C26 -> 0
B42: THE CONSULTATIONS | C42: Surgery consultation (new)
B43: Please fill in table for each consultation | H43: complete field above
B44: 2
B45: Patient reference: | C45: ='Record Audit'!E2 -> 0 | G45: Date of consultation: | I45: ='Record Audit'!E3 -> 0
B47: Consultation Record (copy from clinical system if possible)
B51: Acceptable | C51: Click on the cell to the left and use the drop down list to select the overall rating of the consultation | E51: Comments / Actions required
C54: Scores for each criteria
B55: A | C55: ='Record Audit'!D24 -> 0
B56: C | C56: ='Record Audit'!D25 -> 0 | D56: Total
B57: U | C57: ='Record Audit'!D26 -> 0
B59: THE CONSULTATIONS | C59: Surgery consultation (f/u)
B60: Please fill in table for each consultation | H60: complete field above
B61: 3
B62: Patient reference: | C62: ='Record Audit'!F2 -> 0 | G62: Date of consultation: | I62: ='Record Audit'!F3 -> 0
B64: Consultation Record (copy from clinical system if possible)
B68: Acceptable | C68: Click on the cell to the left and use the drop down list to select the overall rating of the consultation | E68: Comments / Actions required
C71: Scores for each criteria
B72: A | C72: ='Record Audit'!E24 -> 0
B73: C | C73: ='Record Audit'!E25 -> 0 | D73: Total
B74: U | C74: ='Record Audit'!E26 -> 0
...

Sheet Criteria Guidance
B1: Criteria | C1: Explanatory Guidance
A2: 1 | B2: Are the notes coherent and well-structured and include all contacts? | C2: Acceptable (A)
C3: Consultation recorded logically and coherently using either appropriate fields or templates. All contacts recorded
C4: Cause for concern (C)
C5: Consultation recorded logically and coherently using either appropriate fields or templates but not all contacts recorded
C6: Unacceptable (U)
C7: Consultation poorly recorded using neither appropriate fields nor templates. Key contacts and information missing
A8: 2 | B8: Problem appropriately summarised and Read coded | C8: Acceptable (A)
C9: Problem appropriately summarised and Read coded
C10: Unacceptable (U)
C11: Problem not appropriately summarised or Read coded
A12: 3 | B12: Is there a record of the history of the presenting complaint with documentation of relevant positive features? | C12: Acceptable (A)
C13: Should be appropriate to the problem.
C14: The whole entry should be understandable without reliance on other entries.
C15: Cause for concern (C)
C16: Text difficult to follow or omits a key feature.
C17: Unacceptable (U)
C18: No entry or omits key features likely to impact on patient care.
A19: 4 | B19: Is there a record of the history of the presenting complaint with documentation of relevant negative features? | C19: Acceptable (A)
C20: Should be appropriate to the problem.
C21: The whole entry should be understandable without reliance on other entries.
C22: Cause for concern (C)
C23: Text difficult to follow or omits a key feature.
C24: Unacceptable (U)
C25: No entry or omits key features likely to impact on patient care.
A26: 5 | B26: Is there a record of any relevant clinical examination findings? | C26: Acceptable (A)
C27: Should be appropriate to the problem.
C28: The whole entry should be understandable without reliance on other entries.
C29: Cause for concern (C)
C30: Text difficult to follow or omits a key feature.
C31: Unacceptable (U)
C32: No entry or omits key features likely to impact on patient care.
A33: 6 | B33: Makes appropriate diagnostic decisions based on the information acquired, including referral, with a recording of the working diagnosis | C33: Acceptable (A)
C34: Makes appropriate diagnostic and referral decisions based on the information acquired with a recording of the working diagnosis
C35: Cause for concern (C)
C36: Makes appropriate diagnostic and referral decisions based on the information acquired but fails to record the working diagnosis or consider alternatives
C37: Unacceptable (U)
C38: Makes inappropriate diagnostic and referral decisions based on the information acquired with either no recording of the working diagnosis
A39: 7 | B39: Is the prescribing for this consultation within current acceptable guidelines? | C39: Acceptable (A)
C40: Indication is clear and if prescribing is outside guidelines, then this is documented.
...

Sheet Final Assessment
A2: Overall Assessment
A6: ANP
A7: ACP Type:
A8: Clinical Supervisor
C9: Type | F9: Numbers
A10: Setting | C10: Surgery consultation (new)
C11: Surgery consultation (f/u)
C12: Telephone consultation
C13: Home visit
C14: Other
C15: Video
C16: Econsult
A18: Coments and overall actions
A20: Consider :
A22: Prescribing with scope of competence
A23: In line with Local Forumlary
A24: Safety netting
A25: Learning needs
A29: Action plan / Areas to address ( if required)
B48: RAG | C48: Scoring | D48: Comment | E48: Action
B49: Rating
B50: Green | C50: 90-100% | D50: Excellent. Consultation notes are of a high standard. | E50: Clinician progresses to 3 monthly review
B51: Yellow | C51: 70-89% | D51: Good. Minor errors/omissions are present but consultation notes are generally good and of an acceptable standard. | E51: Clinician progresses to 3 monthly review
B52: Amber | C52: 50-69% | D52: Below Standards. Consultations contain more errors/omissions and generally need improvement. Clinicians will be provided with feedback and expected to show improvement for the next review. | E52: Clinician progresses to 1 month review. If no improvement in the next month (RAG yellow or above) face to face review with Partner. If no improvement following this, escalation to Management Partner and consider actions as per Red RAG rating.
B53: Red | C53: <50% | D53: Unacceptable. Consultations are of a poor quality with poor/absent documentation | E53: Inform Management Partner / HR Lead. Face to face review with clinician. Consider additional training/support. A locum GP may not be booked for further shifts after discussion with the Management Parnter / HR Lead.
